Workbook

Sheet Instrucciones
A1: ⚠ ARCHIVO DE PRUEBA CON DATOS FICTICIOS. NO USAR COMO RESULTADO REAL.
A3: Verificación manual de la prerrevisión con IA – Booksy UCAB (PACS 7.2)
A5: Las celdas amarillas son las que se llenan. Elige el valor con la flecha de la celda; no hace falta escribirlo.
A7: Hoja «Verificación»: los 83 hallazgos de la IA
A8: • Columna «resultado»: confirmado (es un defecto real) · falso_positivo (no es defecto) · pendiente (sin revisar).
A9: • «revisor» y «comentario» son opcionales; el comentario conviene en los falsos positivos.
A10: • Las filas grises (No, duplicado) no cuentan en el cálculo: basta con revisar su original.
A12: Hoja «Defectos nuevos»: lo que el equipo encontró y la IA no (falsos negativos)
A13: • Obligatorio: «artefacto». Recomendado: «criterio», «severidad» y «evidencia». El resto es opcional.
A14: • Las filas sin artefacto se ignoran.
A16: Hoja «Resumen»: se calcula sola mientras llenan (precisión y EDD de la IA).
A18: Al terminar: guardar como .xlsx en la carpeta datos/ del repo y ejecutar python3 metricas_sqa.py
A20: Ejemplo de una fila de «Defectos nuevos» (solo de muestra, no se cuenta):
A21: id | B21: artefacto | C21: lista | D21: item | E21: criterio | F21: severidad | G21: secciones | H21: unidades | I21: evidencia | J21: revisor
A22: M-01 | B22: ERS | C22: 1 | D22: HU-12 | E22: Completitud | F22: Mayor | G22: ERS-HU3 | H22: HU3 | I22: La HU3 no contempla qué pasa si se pierde la conexión | J22: Antonio

Sheet Verificación
A1: id | B1: cuenta_en_metricas | C1: artefacto | D1: lista | E1: item | F1: criterio | G1: severidad | H1: duplicado_de | I1: evidencia | J1: resultado | K1: revisor | L1: comentario
A2: L1-HU02-HU2 | B2: Sí | C2: ERS | D2: 1 | E2: HU-02 | F2: Coherente | G2: Menor | I2: Nombre de épica distinto al Brief («Libro») | J2: falso_positivo | K2: (PRUEBA) | L2: (PRUEBA) falso positivo ficticio
A3: L1-HU02-HU3 | B3: Sí | C3: ERS | D3: 1 | E3: HU-02 | F3: Coherente | G3: Menor | I3: Nombre de épica distinto al Brief («Libro») | J3: falso_positivo | K3: (PRUEBA) | L3: (PRUEBA) falso positivo ficticio
A4: L1-HU02-HU4 | B4: Sí | C4: ERS | D4: 1 | E4: HU-02 | F4: Coherente | G4: Menor | I4: Nombre de épica distinto al Brief («Libro») | J4: falso_positivo | K4: (PRUEBA) | L4: (PRUEBA) falso positivo ficticio
A5: L1-HU05-HU2 | B5: Sí | C5: ERS | D5: 1 | E5: HU-05 | F5: Pertinencia | G5: Menor | I5: Dependencia o criterio atado a la base de datos | J5: falso_positivo | K5: (PRUEBA) | L5: (PRUEBA) falso positivo ficticio
A6: L1-HU05-HU4 | B6: Sí | C6: ERS | D6: 1 | E6: HU-05 | F6: Pertinencia | G6: Menor | I6: Dependencia o criterio atado a la base de datos | J6: falso_positivo | K6: (PRUEBA) | L6: (PRUEBA) falso positivo ficticio
A7: L1-HU06-HU1 | B7: Sí | C7: ERS | D7: 1 | E7: HU-06 | F7: Correcto | G7: Menor | I7: Términos vagos (amigable, clara, intuitiva, totalidad) | J7: pendiente | K7: (PRUEBA)
A8: L1-HU06-HU2 | B8: Sí | C8: ERS | D8: 1 | E8: HU-06 | F8: Correcto | G8: Menor | I8: Términos vagos (amigable, clara, intuitiva, totalidad) | J8: pendiente | K8: (PRUEBA)
A9: L1-HU06-HU3 | B9: Sí | C9: ERS | D9: 1 | E9: HU-06 | F9: Correcto | G9: Menor | I9: Términos vagos (amigable, clara, intuitiva, totalidad) | J9: pendiente | K9: (PRUEBA)
A10: L1-HU06-HU4 | B10: Sí | C10: ERS | D10: 1 | E10: HU-06 | F10: Correcto | G10: Menor | I10: Términos vagos (amigable, clara, intuitiva, totalidad) | J10: pendiente | K10: (PRUEBA)
A11: L1-HU08-HU2 | B11: Sí | C11: ERS | D11: 1 | E11: HU-08 | F11: Completitud | G11: Menor | I11: Sin restricciones declaradas | J11: confirmado | K11: (PRUEBA)
A12: L1-HU09-HU2 | B12: Sí | C12: ERS | D12: 1 | E12: HU-09 | F12: Correcto | G12: Mayor | I12: «Datos coherentes» y «mismo libro» sin definir | J12: confirmado | K12: (PRUEBA)
A13: L1-HU09-HU4 | B13: Sí | C13: ERS | D13: 1 | E13: HU-09 | F13: Correcto | G13: Menor | I13: «Verificado como comprador» sin proceso | J13: confirmado | K13: (PRUEBA)
A14: L1-HU11-HU1 | B14: Sí | C14: ERS | D14: 1 | E14: HU-11 | F14: Correcto | G14: Mayor | I14: Criterio de interfaz no medible | J14: confirmado | K14: (PRUEBA)
A15: L1-HU11-HU2 | B15: Sí | C15: ERS | D15: 1 | E15: HU-11 | F15: Correcto | G15: Mayor | I15: Criterio de interfaz no medible | J15: confirmado | K15: (PRUEBA)
A16: L1-HU11-HU3 | B16: Sí | C16: ERS | D16: 1 | E16: HU-11 | F16: Correcto | G16: Mayor | I16: Criterio de interfaz no medible | J16: confirmado | K16: (PRUEBA)
A17: L1-HU11-HU4 | B17: Sí | C17: ERS | D17: 1 | E17: HU-11 | F17: Correcto | G17: Mayor | I17: Criterio de interfaz no medible | J17: confirmado | K17: (PRUEBA)
A18: L1-HU12-HU1 | B18: Sí | C18: ERS | D18: 1 | E18: HU-12 | F18: Completitud | G18: Mayor | I18: No cubre falla de conexión o servidor | J18: confirmado | K18: (PRUEBA)
... A29: L2-HC03 | B29: Sí | C29: ERS | D29: 2 | E29: HC-03 | F29: Coherente | G29: Mayor | I29: ERS 4 HU frente a 13 HU del DAS en el Sprint 1 | J29: confirmado | K29: (PRUEBA)
A30: L2-HC04 | B30: No (duplicado) | C30: ERS | D30: 2 | E30: HC-04 | F30: Coherente | G30: Menor | H30: L1-HU02-HU2, L1-HU02-HU3, L1-HU02-HU4 | I30: Épica con tres nombres | J30: falso_positivo | L30: (PRUEBA) duplicado: no debe contar
A31: L2-HC07 | B31: Sí | C31: ERS | D31: 2 | E31: HC-07 | F31: Completitud | G31: Menor | I31: 2.2.1 y 2.4.1 no reflejados en HU | J31: confirmado | K31: (PRUEBA)
A32: L2-HC09 | B32: No (duplicado) | C32: ERS | D32: 2 | E32: HC-09 | F32: Pertinencia | G32: Menor | H32: L1-HU15-HU1, L1-HU15-HU2, L1-HU15-HU3, L1-HU15-HU4 | I32: Sin prioridad por release | J32: falso_positivo | L32: (PRUEBA) duplicado: no debe contar
A33: L2-HC10 | B33: Sí | C33: ERS | D33: 2 | E33: HC-10 | F33: Completitud | G33: Menor | I33: 1.2 Sprint 2 en el índice, ausente en el cuerpo | J33: confirmado | K33: (PRUEBA)
A34: L3-RF01 | B34: Sí | C34: ERS | D34: 3 | E34: RF-01 | F34: Completitud | G34: Mayor | I34: Faltan 7 HU del Release 1 | J34: confirmado | K34: (PRUEBA)
A35: L3-RF02 | B35: No (duplicado) | C35: ERS | D35: 3 | E35: RF-02 | F35: Completitud | G35: Mayor | H35: L4-RN12, L4-RN13, L4-RN14, L4-RN15, L4-RN17 | I35: Sin requisitos de Seguridad ni Fiabilidad | J35: falso_positivo | L35: (PRUEBA) duplicado: no debe contar
A36: L3-RF03 | B36: Sí | C36: ERS | D36: 3 | E36: RF-03 | F36: Completitud | G36: Menor | I36: Portada 1.0, histórico hasta 1.3 | J36: confirmado | K36: (PRUEBA)
A37: L3-RF05 | B37: Sí | C37: ERS | D37: 3 | E37: RF-05 | F37: Completitud | G37: Mayor | I37: Falta el rol visitante | J37: confirmado | K37: (PRUEBA)
A38: L3-RF06 | B38: Sí | C38: ERS | D38: 3 | E38: RF-06 | F38: Pertinencia | G38: Menor | I38: Sin flujos alternos ni postcondiciones | J38: confirmado | K38: (PRUEBA)
A39: L3-RF07 | B39: Sí | C39: ERS | D39: 3 | E39: RF-07 | F39: Pertinencia | G39: Mayor | I39: Sin atributos del libro ni formato de correo y contraseña | J39: confirmado | K39: (PRUEBA)
A40: L3-RF08 | B40: Sí | C40: ERS | D40: 3 | E40: RF-08 | F40: Pertinencia | G40: Mayor | I40: Alcance de HU1 y HU4 menor al del Brief | J40: confirmado | K40: (PRUEBA)
A41: L3-RF09 | B41: No (duplicado) | C41: ERS | D41: 3 | E41: RF-09 | F41: Correcto | G41: Mayor | H41: L4-RN07, L4-RN08, L4-RN10 | I41: Suplementarios no verificables | J41: falso_positivo | L41: (PRUEBA) duplicado: no debe contar
A42: L3-RF10 | B42: No (duplicado) | C42: ERS | D42: 3 | E42: RF-10 | F42: Correcto | G42: Mayor | H42: L1-HU09-HU2, L1-HU06-HU4 | I42: «Datos coherentes» y «totalidad… sin fallos» | J42: falso_positivo | L42: (PRUEBA) duplicado: no debe contar
A43: L3-RF11 | B43: No (duplicado) | C43: ERS | D43: 3 | E43: RF-11 | F43: Correcto | G43: Menor | H43: L1-HU06-HU1, L1-HU06-HU2, L1-HU06-HU3, L1-HU06-HU4 | I43: Términos vagos | J43: falso_positivo | L43: (PRUEBA) duplicado: no debe contar
A44: L3-RF12 | B44: No (duplicado) | C44: ERS | D44: 3 | E44: RF-12 | F44: Coherente | G44: Mayor | H44: L4-RN17, L4-RN09 | I44: Sin seguridad ni criterio de navegación | J44: falso_positivo | L44: (PRUEBA) duplicado: no debe contar
A45: L3-RF13 | B45: No (duplicado) | C45: ERS | D45: 3 | E45: RF-13 | F45: Coherente | G45: Mayor | H45: L2-HC02, L3-RF01 | I45: HU3 de Release 2 y épicas no cubiertas | J45: falso_positivo | L45: (PRUEBA) duplicado: no debe contar
A46: L3-RF14 | B46: No (duplicado) | C46: ERS | D46: 3 | E46: RF-14 | F46: Coherente | G46: Mayor | H46: L1-HU13-HU2, L1-HU13-HU4 | I46: Tiempos incoherentes | J46: falso_positivo | L46: (PRUEBA) duplicado: no debe contar
A47: L4-RN02 | B47: Sí | C47: ERS | D47: 4 | E47: RN-02 | F47: Completitud | G47: Mayor | I47: Sin condiciones de medición | J47: confirmado | K47: (PRUEBA)
A48: L4-RN03 | B48: No (duplicado) | C48: ERS | D48: 4 | E48: RN-03 | F48: Coherente | G48: Mayor | H48: L1-HU13-HU2, L1-HU13-HU4 | I48: Tiempos de HU frente a 2.1.1 | J48: falso_positivo | L48: (PRUEBA) duplicado: no debe contar
A49: L4-RN05 | B49: Sí | C49: ERS | D49: 4 | E49: RN-05 | F49: Completitud | G49: Menor | I49: No indica qué se verifica ni dispositivos | J49: confirmado | K49: (PRUEBA)
A50: L4-RN07 | B50: Sí | C50: ERS | D50: 4 | E50: RN-07 | F50: Correcto | G50: Mayor | I50: Errores de usuario sin definir | J50: confirmado | K50: (PRUEBA)
...

Sheet Defectos nuevos
A1: id | B1: artefacto | C1: lista | D1: item | E1: criterio | F1: severidad | G1: secciones | H1: unidades | I1: evidencia | J1: revisor
A2: M-01 | B2: ERS | C2: 1 | D2: HU-12 | E2: Completitud | F2: Mayor | G2: ERS-HU3 | H2: HU3 | I2: (PRUEBA) La HU3 no contempla pérdida de conexión | J2: (PRUEBA)
A3: M-02 | B3: ERS | C3: 4 | D3: RN-05 | E3: Correcto | F3: Menor | G3: ERS-221 | H3: 2.2.1 | I3: (PRUEBA) Navegadores soportados sin versión | J3: (PRUEBA)
A4: M-03 | B4: ERS | C4: 3 | D4: RF-05 | E4: Completitud | F4: Mayor | G4: ERS-11 | I4: (PRUEBA) Falta el rol administrador | J4: (PRUEBA)
A5: M-04 | B5: ERS | C5: 2 | D5: HC-07 | E5: Coherente | F5: Menor | G5: ERS-11 | I5: (PRUEBA) Prioridad distinta a la del Brief | J5: (PRUEBA)
A6: M-05 | B6: DAS | C6: 5 | D6: AR-10 | E6: Completitud | F6: Mayor | G6: DAS-152 | I6: (PRUEBA) Falta la vista de despliegue | J6: (PRUEBA)
A7: M-06 | B7: DAS | C7: 5 | D7: AR-16 | E7: Coherente | F7: Menor | G7: DAS-151 | I7: (PRUEBA) Diagrama de contexto sin leyenda | J7: (PRUEBA)
A8: M-07 | B8: Brief | C8: B | D8: B-02 | E8: Pertinencia | F8: Menor | G8: BR-MHU | I8: (PRUEBA) Épica fuera del alcance del MVP | J8: (PRUEBA)
A9: M-08
A10: M-09
A11: M-10
A12: M-11
A13: M-12
A14: M-13
A15: M-14
A16: M-15
A17: M-16
A18: M-17
A19: M-18
A20: M-19
... A61: M-60

Sheet Resumen
A1: Resumen de la verificación (se actualiza solo)
A3: Artefacto | B3: Hallazgos IA (únicos) | C3: Confirmados | D3: Falsos positivos | E3: Pendientes | F3: Nuevos del equipo | G3: Precisión IA | H3: EDD IA
A4: ERS | B4: =COUNTIFS(Verificación!$B$2:$B$84,"Sí",Verificación!$C$2:$C$84,$A4) -> 49 | C4: =COUNTIFS(Verificación!$B$2:$B$84,"Sí",Verificación!$C$2:$C$84,$A4,Verificación!$J$2:$J$84,"confirmado") -> 40 | D4: =COUNTIFS(Verificación!$B$2:$B$84,"Sí",Verificación!$C$2:$C$84,$A4,Verificación!$J$2:$J$84,"falso_positivo") -> 5 | E4: =B4-C4-D4 -> 4 | F4: =COUNTIF('Defectos nuevos'!$B$2:$B$61,$A4) -> 4 | G4: =IF(C4+D4=0,"-",C4/(C4+D4)) -> 0.88888889 | H4: =IF(C4+F4=0,"-",C4/(C4+F4)) -> 0.90909091
A5: DAS | B5: =COUNTIFS(Verificación!$B$2:$B$84,"Sí",Verificación!$C$2:$C$84,$A5) -> 14 | C5: =COUNTIFS(Verificación!$B$2:$B$84,"Sí",Verificación!$C$2:$C$84,$A5,Verificación!$J$2:$J$84,"confirmado") -> 12 | D5: =COUNTIFS(Verificación!$B$2:$B$84,"Sí",Verificación!$C$2:$C$84,$A5,Verificación!$J$2:$J$84,"falso_positivo") -> 2 | E5: =B5-C5-D5 -> 0 | F5: =COUNTIF('Defectos nuevos'!$B$2:$B$61,$A5) -> 2 | G5: =IF(C5+D5=0,"-",C5/(C5+D5)) -> 0.85714286 | H5: =IF(C5+F5=0,"-",C5/(C5+F5)) -> 0.85714286
A6: Brief | B6: =COUNTIFS(Verificación!$B$2:$B$84,"Sí",Verificación!$C$2:$C$84,$A6) -> 5 | C6: =COUNTIFS(Verificación!$B$2:$B$84,"Sí",Verificación!$C$2:$C$84,$A6,Verificación!$J$2:$J$84,"confirmado") -> 4 | D6: =COUNTIFS(Verificación!$B$2:$B$84,"Sí",Verificación!$C$2:$C$84,$A6,Verificación!$J$2:$J$84,"falso_positivo") -> 1 | E6: =B6-C6-D6 -> 0 | F6: =COUNTIF('Defectos nuevos'!$B$2:$B$61,$A6) -> 1 | G6: =IF(C6+D6=0,"-",C6/(C6+D6)) -> 0.8 | H6: =IF(C6+F6=0,"-",C6/(C6+F6)) -> 0.8
A7: Total | B7: =SUM(B4:B6) -> 68 | C7: =SUM(C4:C6) -> 56 | D7: =SUM(D4:D6) -> 8 | E7: =SUM(E4:E6) -> 4 | F7: =SUM(F4:F6) -> 7 | G7: =IF(C7+D7=0,"-",C7/(C7+D7)) -> 0.875 | H7: =IF(C7+F7=0,"-",C7/(C7+F7)) -> 0.88888889
A9: Precisión IA = confirmados / (confirmados + falsos positivos)
A10: EDD IA = confirmados / (confirmados + nuevos del equipo). Umbral del PACS: ≥ 85 %.
A11: =IF(E7>0,"Verificación en curso: "&E7&" de "&B7&" hallazgos sin revisar; cifras parciales.","Verificación completa.") -> Verificación en curso: 4 de 68 hallazgos sin revisar; cifras parciales.
